Workbook

Sheet 2026初客紀錄
B1: 日期 | C1: 客人 來源 | D1: 姓名 | E1: 電話 | F1: 進線初接 | G1: 初次聯絡事項 | H1: 是 | I1: 聯絡人員 | J1: 電話 日期 | K1: 參訪 日期 | L1: 人 數 | M1: 二次邀約狀況 （預算＆規劃＋用途）
A2: 已連絡 | B2: 46014 | C2: FB名單 | D2: 林意馨 | E2: 0912156377 | F2: 謹瀅 | G2: 你好：今日方便參觀嗎？ 今天剛好有空要上台中，所以想說今天是否方便參觀 住家在高雄 | I2: 謹瀅 | J2: 46014 | K2: 46130 | L2: 2 | M2: 之前有在花博看過(還沒有買地)，有看過簡章有了解 今年有買地(大湖)-現在有想骰規劃，有水有電， 自己在做生意時間不固定，留近期參訪時間給參考 住：高雄 1/31 榕 3月想來訪(月初出國，月底3/17號以後平日都可以排，每周二是最方便的，依我們安排為主) 2/26許 是餐飲業(配合老公時間安排上來)，3/4-9出國， 想改約4/14，要提前先約時間，方便排休 3/25去電未接，Line再確認四月中的日期
A3: 待確認日期 | B3: 46023 | C3: FB名單 | D3: 許嘉彬 | E3: 0912181737 | F3: 梓涵 | G3: 請問預約下午參觀可以嗎 嘉義建地 4米寬40米深 想放單院屋型 傳照片給她 (後台) | H3: 是 | I3: 子榕 | J3: 46024 | M3: 臨時想來訪，後續要北上安排時間，才會方便 3/25 去電，近期可能會出國，要來再預約時間
A4: 已連絡 | B4: 46023 | C4: FB名單 | D4: 李小姐 | E4: 0988021266 | F4: 梓涵 | G4: 請問你們過年有營業嗎? (電話中已經回2/15~2/23年節假期) (看起來是想用餐+參觀木屋) 1/2 未接通2 | H4: 是 | I4: 子榕 | J4: 46025 | M4: 1/3許 未接2 早期的家具客戶，沒有自主移動能力，一定要找小孩載送 有一點興趣，沒地。自己會再回電
A5: 已連絡 | B5: 46023 | C5: FB名單 | D5: 林育生 | E5: 0982861116 | F5: 梓涵 | G5: 一家三口, 想了解屋款價格範圍 | H5: 是 | I5: 謹瀅 | J5: 46023 | K5: 46025 | L5: 2 | M5: 地在鹿港，老婆是鹿港人，想給小孩還有老婆一個新環境 目前不想透漏太多，看不太懂網址內容
A6: 連絡中 | B6: 46024 | C6: FB名單 | D6: 李小姐 | E6: 0911800625 | G6: 您好，想先請問木屋大概基礎的價格，如13坪數，或是更大的。 地點：苗栗泰安或是台東。 | I6: 梓涵 | J6: 46133 | M6: 想蓋30坪左右，有考慮旗艦兩組想要合併，3-5為家人一起住， 有再考慮其他小木屋及我們，可能是3位參訪 有問費用300(感覺貴)，所以說需要評估，有需要再連絡 4/21 語音
A7: 待確認日期 | B7: 46024 | C7: FB名單 | D7: 范先生 | E7: 0937962912 | F7: 梓涵 | G7: 我們有一塊地在苗栗的丙建 坪數100初~可蓋ˇ30~40坪 明天2點參觀時間會來不及,可另約時間 | H7: 是 | I7: 謹瀅 | J7: 46025 | M7: 目前感覺不想透漏太多，但態度尚可 請他加LINE，再傳預約資訊 1/3 太太尚未確認，日期先取消
A8: 已連絡 | B8: 46024 | C8: FB名單 | D8: 簡廷宇 | E8: 0986557980 | G8: 想了解，週六全天可聯繫 有地的參觀 (後台) | I8: 子榕 | J8: 46025 | M8: 最少1位，農地 有電沒水 南投 草屯 特農。因為是當地人，沒有想法規劃。 木屋坪數? (說不喜歡大坪數) 一直說他對這個生活很有興趣，不但問到化糞池有沒有包、基座有沒有 包、庭園有沒有包、種菜有沒有包????????????? 感覺 "真的" 很像同行 (太空艙?)
A9: 已連絡 | B9: 46024 | C9: FB名單 | D9: 胡智凱 | E9: 0939179626 | F9: 梓涵 | G9: 想參觀木屋(週六較方便) | H9: 是 | I9: 子榕 | J9: 46025 | K9: 46032 | L9: 4 | M9: 參訪：4位 2大2小 (國小1年級3年級) 先跟胡先生說明小孩的部分，他晚點跟太太討論，決定還是要帶小孩參訪
A10: 暫置 | B10: 46025 | C10: FB名單 | D10: Douglas Lin | E10: 0928829256 | F10: 子榕 | G10: 平日早上0900-1200 "1/7 未接通2 1/8許 掛電話2" | H10: 是 | J10: 46029 | M10: 未接，1/8許 掛電話2
A11: 暫置 | B11: 46025 | C11: FB名單 | D11: 陳信介 | E11: 0917273250 | F11: 子榕 | G11: 平日早上0900-1200 | H11: 是 | J11: 46029 | M11: 開會中，說要LINE給他．．．就掛電話 沒有LINE阿 ＝ ＝
A12: 暫置 | B12: 46025 | C12: FB名單 | D12: 陳淑津 | E12: 0919207558 | F12: 子榕 | G12: 平日下午1300-1800 1/6許 10分鐘後未接 | H12: 是 | J12: 46028 | M12: 未接，10分鐘後未接
A13: 暫置 | B13: 46025 | C13: FB名單 | D13: Joanne Wang | E13: 0952490535 | F13: 子榕 | G13: 週六下午1300-1800 "有語音 看看此人是誰該不該接聽電話 已留言 我們是自然紅屋" | H13: 是 | J13: 46025 | M13: 語音
A14: 暫置 | B14: 46025 | C14: FB名單 | D14: 洪先生 | E14: 0930992255 | F14: 謹瀅 | G14: 我在你們外面，我要參觀你們行動木屋， 有跟他說要預約，他說給他資料下次他再過來， 很沒有禮貌的人，有跟他說可以加LINE先預約 1/7 未接通2 | H14: 是 | J14: 46029 | M14: 未接
A15: 連絡中 | B15: 46025 | C15: FB名單 | D15: 王月娥 | E15: 0953551112 | F15: 子榕 | G15: 週六下午1300-1800 | H15: 是 | I15: 謹瀅 | J15: 46025 | M15: 林先生(留媽媽的聯絡資料) 之前住石岡附近，有來參觀過，有買過家具(很多) 目前有兩塊地閒置(頭份、三義)，有考慮其他廠商， 不想申請建照，想用農地就好 資料還沒看有請他加LINE(有傳資料給本人)
A16: 連絡中 | B16: 46025 | C16: FB名單 | D16: 王復儒 | E16: 0933218908 | F16: 謹瀅 | G16: 平日下午1300-1800 | H16: 是 | J16: 46029 | M16: 1/6許 說現在有點忙稍後會回覆 1/7 先生推給太太，說還在忙，看完資料會主動回覆
A17: 連絡中 | B17: 46025 | C17: FB名單 | D17: 郭仲強 | E17: 0928577282 | F17: 梓涵 | G17: 有基地的參觀 週六較方便安排 2大2小 | H17: 是 | I17: 子榕 | J17: 46025 | M17: 參訪： 夫妻+小孩 3y5y 小孩已告知，待確定要帶進來還是請親戚幫忙再公園照顧
A18: 待確認日期 | B18: 46025 | C18: FB名單 | D18: 蕭小姐 | E18: 0980585177 | F18: 子榕 | G18: 無地的參觀 1/3 未接通3 1/6許 週六方便聯絡 | H18: 是 | I18: 謹瀅 | J18: 46032 | M18: 在尋找土地中，想先來參觀了解。 為之後4、50歲的生活做規劃(感覺可以推體驗營~) 工作在台北、有房在桃園，是中南部人， 感覺是小白，不知道要買建地或農地， 有問土地媒介，因為一直沒有找到適合的土地， 感覺也可以推后土紅友計畫， 有請她加LINE，目前參觀時間待確認(假日比較有空)
A19: 待確認日期 | B19: 46025 | C19: FB名單 | D19: 林兆啟 | E19: 0905510269 | F19: 子榕 | G19: 平日早上0900-1200 | H19: 是 | I19: 子榕 | J19: 46029 | M19: 住潭子，1 聽說現在蓋木屋很貴，有想法但想先來看看 (看了參訪尚未看價格)
A20: 已連絡 | B20: 46025 | C20: FB名單 | D20: 張益彰 | E20: 0932587239 | F20: 子榕 | G20: 平日下午1300-1800 | H20: 是 | I20: 梓涵 | J20: 46025 | M20: 本身是{847露營區}經營者 想加蓋,目前很多廠商在評估中 基地在南投的竹山、鹿谷都有 因為有蓋過木屋,組合屋的經驗 想大概了解我們的材質資訊等等 再去評估自己值不值跑這一趟參觀 300園參觀費不是問題,覺得2~3小時太久 先寄資料
A21: 已連絡 | B21: 46025 | C21: FB名單 | D21: 鄭先生 | E21: 0923320449 | F21: 子榕 | G21: 平日下午1300-1800 | H21: 是 | I21: 謹瀅 | J21: 46028 | M21: 有請他加LINE，想預約下禮拜參訪 LINE回覆有需要會再聯絡
A22: 已連絡 | B22: 46025 | C22: FB名單 | D22: 陳小姐Amy | E22: 0933979910 | F22: 子榕 | G22: 平日下午1300-1800 | H22: 是 | I22: 子榕 | J22: 46028 | K22: 46039 | L22: 3 | M22: 無資料
A23: 已連絡 | B23: 46025 | C23: FB名單 | D23: 劉滋芳 | E23: 0987798486 | F23: 子榕 | G23: 平日下午1300-1800 1/6許 空號！！！ | H23: 是 | J23: 46028 | M23: 未接，空號
A24: 已連絡 | B24: 46025 | C24: FB名單 | D24: 張先生 | E24: 0932346656 | F24: 謹瀅 | G24: 週六早上0900-1200 | H24: 是 | I24: 梓涵 | J24: 46032 | K24: 46046 | L24: 2 | M24: 目前找地中~
A25: 已連絡 | B25: 46025 | C25: FB名單 | D25: 賴靜慧 | E25: 0926950022 | F25: 梓涵 | G25: 住台中北屯 有地的參觀 平常也休日一(_居家工作室職業) 目前1/14(三)剛好有空檔可以預約參觀 已經觀察我們行動屋很久了 | H25: 是 | I25: 子榕 | J25: 46030 | K25: 46036 | L25: 1 | M25: 自己參訪 有地
A26: 暫置 | B26: 46026 | C26: FB名單 | D26: Shen Shen 沈晴 | E26: 0988881836 | F26: 謹瀅 | G26: 平日下午1300-1800 1/6許 未接2 1/7 未接通2 1/16 轉語音信箱 | H26: 是 | J26: 46029 | M26: 未接
A27: 暫置 | B27: 46026 | C27: FB名單 | D27: 陳先生 | E27: 0936778553 | F27: 謹瀅 | G27: 平日下午1300-1800 1/6許 現在開會明早可以聯絡~ 1/7 語音信箱 | H27: 是 | J27: 46029 | M27: 語音
A28: 連絡中 | B28: 46026 | C28: FB名單 | D28: 黃添本 | E28: 0919780443 | F28: 謹瀅 | G28: 平日早上0900-1200 訊號不好，掛電話。 然後就不接了 | H28: 是 | I28: 子榕 | J28: 46028 | M28: 未接
A29: 連絡中 | B29: 46026 | C29: FB名單 | D29: Zong Yi | E29: 0981919648 | F29: 謹瀅 | G29: 平日早上0900-1200 1/7 未接通2 | H29: 是 | J29: 46030 | M29: 1/8許 在忙中，晚點會自行連絡
A30: 連絡中 | B30: 46026 | C30: FB名單 | D30: Liu Foot | E30: 0919048616 | F30: 謹瀅 | G30: 週六下午1300-1800 | H30: 是 | I30: 謹瀅 | J30: 46038 | M30: 根本沒看資料
A31: 已連絡 | B31: 46026 | C31: FB名單 | D31: Louise Shih 石小姐 | E31: 0928718131 | F31: 謹瀅 | G31: 平日早上0900-1200 | H31: 是 | I31: 謹瀅 | J31: 46030 | K31: 46036 | L31: 1 | M31: 之前看過太空艙(說有仲介配合找土地，感覺是想要不勞而獲)， 目前想要先了解，已加LINE聯絡
A32: 已連絡 | B32: 46026 | C32: FB名單 | D32: michael wei | E32: 0934168943 | F32: 謹瀅 | G32: 週六早上0900-1200 | H32: 是 | I32: 謹瀅 | J32: 46038 | M32: 以為我們是建商，說不需要
A33: 已連絡 | B33: 46026 | C33: FB名單 | D33: 羅仕昇 | E33: 0919677872 | F33: 謹瀅 | G33: 週六早上0900-1200 | H33: 是 | I33: 梓涵 | J33: 46032 | K33: 46039 | L33: 1 | M33: 老家東勢土地(目前是與親戚聯名) 農地為平地 屋款資訊沒有仔細看 平常在新竹工作
A34: 暫置 | B34: 46027 | C34: FB名單 | D34: Lily Hsiao 蕭豐姿 | E34: 0953009698 | F34: 謹瀅 | G34: 平日早上0900-1200 1/8許 語音信箱2 | H34: 是 | J34: 46030 | M34: 語音
A35: 暫置 | B35: 46027 | C35: FB名單 | D35: 洪開燁 | E35: 0937106760 | F35: 謹瀅 | G35: 平日下午1300-1800 1/7 未接通2 | H35: 是 | J35: 46029 | M35: 未接
A36: 暫置 | B36: 46027 | C36: FB名單 | D36: 黃怡伶 | E36: 0971671970 | F36: 謹瀅 | G36: 平日下午1300-1800 1/7 未接通2 | H36: 是 | J36: 46029 | M36: 未接
A37: 暫置 | B37: 46027 | C37: FB名單 | D37: 廖國丞 | E37: 0980734825 | F37: 謹瀅 | G37: 平日下午1300-1800 | H37: 是 | I37: 謹瀅 | J37: 46038 | M37: 語音
A38: 連絡中 | B38: 46027 | C38: FB名單 | D38: 林貴美 | E38: 0985375557 | F38: 謹瀅 | G38: 平日早上0900-1200 | H38: 是 | J38: 46030 | M38: 取消預約，已刪LINE
A39: 已連絡 | B39: 46027 | C39: FB名單 | D39: 徐雯柳 | E39: 0910922276 | F39: 謹瀅 | G39: guantoushan93@gmail.com 有地參觀 | H39: 是 | I39: 謹瀅 | J39: 46029 | K39: 46031 | L39: 4 | M39: 朋友有買地，朋推薦我們不錯，覺得可以的話就想直接買， 一群退休的朋友，總共4位， 人在外面，有請她加LINE
A40: 已連絡 | B40: 46027 | C40: FB名單 | D40: 葉方杰 | E40: 0921300049 | F40: 謹瀅 | G40: 平日下午1300-1800 | H40: 是 | I40: 子榕 | J40: 46029 | M40: 1/6許 還沒看資料 沒有要看
...

Sheet 今年整年的月電話量
A1: 總電話量 | E1: 月份 | F1: FB名單 純表單 | I1: 其他管道 FB LINE WIX 後台 GM 其他 TEL | M1: 各人員電話邀約成功率 | S1: 篩選器 (手動)電話日期&聯絡人員
A2: 月份 | B2: 每月份(可下拉) | C2: 手動驗證) | F2: 數量 | G2: 預約成功 | H2: % | I2: 數量 | J2: 預約成功 | K2: % | M2: 月份 | N2: 人員 | O2: 撥通電話 | P2: 邀約成功 | Q2: 成功率 % | S2: 撥通電話 | V2: 邀約成功 | Y2: 空包彈 = 未接、語音、其他無法接通項目
A3: =DATE(2026,1,1) -> 46023 | B3: =COUNTIFS('2026初客紀錄'!B:B, ">=" & A3,'2026初客紀錄'!B:B, "<" & EDATE(A3, 1)) -> 218 | C3: =COUNTIFS('2026初客紀錄'!B:B,">=2026/1/1",'2026初客紀錄'!B:B,"<=2026/1/31") -> 218 | E3: 1 | F3: =COUNTIFS('2026初客紀錄'!B:B,">=2026/1/1",'2026初客紀錄'!B:B,"<=2026/1/31",'2026初客紀錄'!C:C,"FB名單") -> 218 | G3: =COUNTIFS('2026初客紀錄'!B:B,">=2026/1/1",'2026初客紀錄'!B:B,"<=2026/1/31",'2026初客紀錄'!C:C,"FB名單",'2026初客紀錄'!K:K,"<>") -> 43 | H3: =G3/F3 -> 0.19724771 | I3: =B3-F3 -> 0 | J3: =J27-G3 -> 0 | K3: =J3/I3 -> #DIV/0! | M3: 1月 | N3: 子榕 | O3: 67 | P3: 16 | Q3: =P3/O3 -> 0.23880597 | S3: 電話 日期 | T3: 聯絡人員的COUNTA | V3: 電話 日期 | W3: 參訪 日期的COUNTA | Y3: 電話 日期 | Z3: 聯絡人員的COUNTA
A4: =EDATE(A3,1) -> 46054 | B4: =COUNTIFS('2026初客紀錄'!B:B, ">=" & A4,'2026初客紀錄'!B:B, "<" & EDATE(A4, 1)) -> 107 | C4: =COUNTIFS('2026初客紀錄'!B:B,">=2026/2/1",'2026初客紀錄'!B:B,"<=2026/2/28") -> 107 | E4: 2 | F4: =COUNTIFS('2026初客紀錄'!B:B,">=2026/2/1",'2026初客紀錄'!B:B,"<=2026/2/28",'2026初客紀錄'!C:C,"FB名單") -> 107 | G4: =COUNTIFS('2026初客紀錄'!B:B,">=2026/2/1",'2026初客紀錄'!B:B,"<=2026/2/28",'2026初客紀錄'!C:C,"FB名單",'2026初客紀錄'!K:K,"<>") -> 14 | H4: =G4/F4 -> 0.13084112 | I4: =B4-F4 -> 0 | J4: =J28-G4 -> 0 | K4: =J4/I4 -> #DIV/0! | M4: 1月 | N4: 梓涵 | O4: 53 | P4: 13 | Q4: =P4/O4 -> 0.24528302 | S4: 46238 | T4: 9 | V4: 46238 | W4: 0 | Y4: 46238 | Z4: 2
A5: =EDATE(A4,1) -> 46082 | B5: =COUNTIFS('2026初客紀錄'!B:B, ">=" & A5,'2026初客紀錄'!B:B, "<" & EDATE(A5, 1)) -> 134 | C5: =COUNTIFS('2026初客紀錄'!B:B,">=2026/3/1",'2026初客紀錄'!B:B,"<=2026/3/31") -> 134 | E5: 3 | F5: =COUNTIFS('2026初客紀錄'!B:B,">=2026/3/1",'2026初客紀錄'!B:B,"<=2026/3/31",'2026初客紀錄'!C:C,"FB名單") -> 134 | G5: =COUNTIFS('2026初客紀錄'!B:B,">=2026/3/1",'2026初客紀錄'!B:B,"<=2026/3/31",'2026初客紀錄'!C:C,"FB名單",'2026初客紀錄'!K:K,"<>") -> 38 | H5: =G5/F5 -> 0.28358209 | I5: =B5-F5 -> 0 | J5: =J29-G5 -> 0 | K5: =J5/I5 -> #DIV/0! | M5: 1月 | N5: 謹瀅 | O5: 69 | P5: 12 | Q5: =P5/O5 -> 0.17391304 | S5: 46239 | T5: 4 | V5: 46239 | W5: 2 | Y5: 46242 | Z5: 3
A6: =EDATE(A5,1) -> 46113 | B6: =COUNTIFS('2026初客紀錄'!B:B, ">=" & A6,'2026初客紀錄'!B:B, "<" & EDATE(A6, 1)) -> 46 | C6: =COUNTIFS('2026初客紀錄'!B:B,">=2026/4/1",'2026初客紀錄'!B:B,"<=2026/4/28") -> 41 | E6: 4 | F6: =COUNTIFS('2026初客紀錄'!B:B,">=2026/4/1",'2026初客紀錄'!B:B,"<=2026/4/28",'2026初客紀錄'!C:C,"FB名單") -> 41 | G6: =COUNTIFS('2026初客紀錄'!B:B,">=2026/4/1",'2026初客紀錄'!B:B,"<=2026/4/28",'2026初客紀錄'!C:C,"FB名單",'2026初客紀錄'!K:K,"<>") -> 11 | H6: =G6/F6 -> 0.26829268 | I6: =B6-F6 -> 5 | J6: =J30-G6 -> 0 | K6: =J6/I6 -> 0 | M6: 2月 | N6: 子榕 | O6: 11 | P6: 5 | Q6: =P6/O6 -> 0.45454545 | S6: 46240 | T6: 1 | V6: 46240 | W6: 1 | Y6: 46247 | Z6: 4
A7: =EDATE(A6,1) -> 46143 | B7: =COUNTIFS('2026初客紀錄'!B:B, ">=" & A7,'2026初客紀錄'!B:B, "<" & EDATE(A7, 1)) -> 96 | C7: =COUNTIFS('2026初客紀錄'!B:B,">=2026/5/1",'2026初客紀錄'!B:B,"<=2026/5/31") -> 96 | E7: 5 | F7: =COUNTIFS('2026初客紀錄'!B:B,">=2026/5/1",'2026初客紀錄'!B:B,"<=2026/5/31",'2026初客紀錄'!C:C,"FB名單") -> 96 | G7: =COUNTIFS('2026初客紀錄'!B:B,">=2026/5/1",'2026初客紀錄'!B:B,"<=2026/5/31",'2026初客紀錄'!C:C,"FB名單",'2026初客紀錄'!K:K,"<>") -> 24 | H7: =G7/F7 -> 0.25 | I7: =B7-F7 -> 0 | J7: =J31-G7 -> 0 | K7: =J7/I7 -> #DIV/0! | M7: 2月 | N7: 梓涵 | O7: 57 | P7: 3 | Q7: =P7/O7 -> 0.052631579 | S7: 46242 | T7: 6 | V7: 46242 | W7: 2 | Y7: 46249 | Z7: 4
A8: =EDATE(A7,1) -> 46174 | B8: =COUNTIFS('2026初客紀錄'!B:B, ">=" & A8,'2026初客紀錄'!B:B, "<" & EDATE(A8, 1)) -> 140 | C8: =COUNTIFS('2026初客紀錄'!B:B,">=2026/6/1",'2026初客紀錄'!B:B,"<=2026/6/30") -> 140 | E8: 6 | F8: =COUNTIFS('2026初客紀錄'!B:B,">=2026/6/1",'2026初客紀錄'!B:B,"<=2026/6/30",'2026初客紀錄'!C:C,"FB名單") -> 140 | G8: =COUNTIFS('2026初客紀錄'!B:B,">=2026/6/1",'2026初客紀錄'!B:B,"<=2026/6/30",'2026初客紀錄'!C:C,"FB名單",'2026初客紀錄'!K:K,"<>") -> 30 | H8: =G8/F8 -> 0.21428571 | I8: =B8-F8 -> 0 | J8: =J32-G8 -> 0 | K8: =J8/I8 -> #DIV/0! | M8: 2月 | N8: 謹瀅 | O8: 28 | P8: 6 | Q8: =P8/O8 -> 0.21428571 | S8: 46245 | T8: 4 | V8: 46245 | W8: 3 | Y8: 46255 | Z8: 2
A9: =EDATE(A8,1) -> 46204 | B9: =COUNTIFS('2026初客紀錄'!B:B, ">=" & A9,'2026初客紀錄'!B:B, "<" & EDATE(A9, 1)) -> 115 | C9: =COUNTIFS('2026初客紀錄'!B:B,">=2026/7/1",'2026初客紀錄'!B:B,"<=2026/7/31") -> 115 | E9: 7 | F9: =COUNTIFS('2026初客紀錄'!B:B,">=2026/7/1",'2026初客紀錄'!B:B,"<=2026/7/31",'2026初客紀錄'!C:C,"FB名單") -> 115 | G9: =COUNTIFS('2026初客紀錄'!B:B,">=2026/7/1",'2026初客紀錄'!B:B,"<=2026/7/31",'2026初客紀錄'!C:C,"FB名單",'2026初客紀錄'!K:K,"<>") -> 33 | H9: =G9/F9 -> 0.28695652 | I9: =B9-F9 -> 0 | J9: =J33-G9 -> 0 | K9: =J9/I9 -> #DIV/0! | M9: 3月 | N9: 子榕 | O9: 48 | P9: 8 | Q9: =P9/O9 -> 0.16666667 | S9: 46246 | T9: 3 | V9: 46246 | W9: 3 | Y9: 46256 | Z9: 2
A10: =EDATE(A9,1) -> 46235 | B10: =COUNTIFS('2026初客紀錄'!B:B, ">=" & A10,'2026初客紀錄'!B:B, "<" & EDATE(A10, 1)) -> 109 | C10: =COUNTIFS('2026初客紀錄'!B:B,">=2026/8/1",'2026初客紀錄'!B:B,"<=2026/8/31") -> 109 | E10: 8 | F10: =COUNTIFS('2026初客紀錄'!B:B,">=2026/8/1",'2026初客紀錄'!B:B,"<=2026/8/31",'2026初客紀錄'!C:C,"FB名單") -> 66 | G10: =COUNTIFS('2026初客紀錄'!B:B,">=2026/8/1",'2026初客紀錄'!B:B,"<=2026/8/31",'2026初客紀錄'!C:C,"FB名單",'2026初客紀錄'!K:K,"<>") -> 10 | H10: =G10/F10 -> 0.15151515 | I10: =B10-F10 -> 43 | J10: =J34-G10 -> 16 | K10: =J10/I10 -> 0.37209302 | M10: 3月 | N10: 梓涵 | O10: 64 | P10: 15 | Q10: =P10/O10 -> 0.234375 | S10: 46247 | T10: 11 | V10: 46247 | W10: 3 | Y10: 46260 | Z10: 1
A11: =EDATE(A10,1) -> 46266 | B11: =COUNTIFS('2026初客紀錄'!B:B, ">=" & A11,'2026初客紀錄'!B:B, "<" & EDATE(A11, 1)) -> 6 | C11: =COUNTIFS( '2025初客紀錄'!B:B,">=2025/11/1", '2025初客紀錄'!B:B,"<=2025/11/30" ) -> 0 | E11: 9 | I11: =J11-G11 -> 0 | M11: 3月 | N11: 汝軍 | O11: 14 | P11: 6 | Q11: =P11/O11 -> 0.42857143 | S11: 46249 | T11: 6 | V11: 46249 | W11: 0 | Y11: 46261 | Z11: 6
A12: =EDATE(A11,1) -> 46296 | B12: =COUNTIFS('2026初客紀錄'!B:B, ">=" & A12,'2026初客紀錄'!B:B, "<" & EDATE(A12, 1)) -> 0 | C12: =COUNTIFS( '2025初客紀錄'!B:B,">=2025/12/1", '2025初客紀錄'!B:B,"<=2025/12/31" ) -> 0 | E12: 10 | I12: =J12-G12 -> 0 | M12: 4月 | N12: 子榕 | O12: 11 | P12: 3 | Q12: =P12/O12 -> 0.27272727 | S12: 46252 | T12: 2 | V12: 46252 | W12: 0 | Y12: 46262 | Z12: 1
A13: =EDATE(A12,1) -> 46327 | B13: =COUNTIFS('2026初客紀錄'!B:B, ">=" & A13,'2026初客紀錄'!B:B, "<" & EDATE(A13, 1)) -> 0 | C13: =COUNTIFS( '2025初客紀錄'!B:B,">=2026/1/1", '2025初客紀錄'!B:B,"<=2026/1/31" ) -> 0 | E13: 11 | I13: =J13-G13 -> 0 | M13: 4月 | N13: 梓涵 | O13: 59 | P13: 13 | Q13: =P13/O13 -> 0.22033898 | S13: 46254 | T13: 1 | V13: 46254 | W13: 0 | Y13: 46263 | Z13: 1
A14: =EDATE(A13,1) -> 46357 | B14: =COUNTIFS('2026初客紀錄'!B:B, ">=" & A14,'2026初客紀錄'!B:B, "<" & EDATE(A14, 1)) -> 0 | C14: =COUNTIFS( '2025初客紀錄'!B:B,">=2026/2/1", '2025初客紀錄'!B:B,"<=2026/2/28" ) -> 0 | E14: 12 | I14: =J14-G14 -> 0 | M14: 4月 | N14: 汝軍 | O14: 1 | P14: 1 | Q14: =P14/O14 -> 1 | S14: 46255 | T14: 18 | V14: 46255 | W14: 4 | Y14: 總和 | Z14: 26
M15: 5月 | N15: 子榕 | O15: 19 | P15: 7 | Q15: =P15/O15 -> 0.36842105 | S15: 46256 | T15: 5 | V15: 46256 | W15: 1
A16: 2026 詳細數據 | M16: 5月 | N16: 梓涵 | O16: 67 | P16: 17 | Q16: =P16/O16 -> 0.25373134 | S16: 46259 | T16: 7 | V16: 46259 | W16: 1
A17: 項目 | B17: 數量 | C17: 未撥 | D17: 已撥 | E17: 已接 | F17: 未接+語音 | G17: 其他 無效 | H17: 已接 未約成 | I17: 家具 | J17: 預約 成功 | K17: 成功率 % | M17: 5月 | N17: 汝軍 | O17: 6 | P17: 1 | Q17: =P17/O17 -> 0.16666667 | S17: 46260 | T17: 5 | V17: 46260 | W17: 2
A18: 現場 (ALL) | B18: =COUNTIF('2026初客紀錄'!C:C,"現場") -> 0 | C18: =B18-D18 -> 0 | D18: =COUNTIFS('2026初客紀錄'!C:C,"現場",'2026初客紀錄'!J:J,"<>") -> 0 | E18: =D18-F18-G18 -> 0 | F18: =COUNTIFS('2026初客紀錄'!C:C,"現場",'2026初客紀錄'!M:M,"未接")+COUNTIFS('2026初客紀錄'!C:C,"現場",'2026初客紀錄'!M:M,"語音") -> 0 | G18: =COUNTIFS('2026初客紀錄'!C:C,"現場",'2026初客紀錄'!K:K,"X") -> 0 | H18: =E18-J18 -> 0 | J18: =COUNTIFS('2026初客紀錄'!C:C,"現場",'2026初客紀錄'!K:K,"<>") -> 0 | K18: =J18/D18 -> #DIV/0! | M18: 6月 | N18: 子榕 | O18: 46 | P18: 13 | Q18: =P18/O18 -> 0.2826087 | S18: 46261 | T18: 12 | V18: 46261 | W18: 1
A19: TEL(ALL) | B19: =COUNTIF('2026初客紀錄'!C:C,"TEL") -> 7 | C19: =B19-D19 -> 1 | D19: =COUNTIFS('2026初客紀錄'!C:C,"TEL",'2026初客紀錄'!J:J,"<>") -> 6 | E19: =D19-F19-G19 -> 6 | F19: =COUNTIFS('2026初客紀錄'!C:C,"TEL",'2026初客紀錄'!M:M,"未接")+COUNTIFS('2026初客紀錄'!C:C,"TEL",'2026初客紀錄'!M:M,"語音") -> 0 | G19: =COUNTIFS('2026初客紀錄'!C:C,"TEL",'2026初客紀錄'!K:K,"X") -> 0 | H19: =E19-J19 -> 2 | J19: =COUNTIFS('2026初客紀錄'!C:C,"TEL",'2026初客紀錄'!K:K,"<>") -> 4 | K19: =J19/D19 -> 0.66666667 | M19: 6月 | N19: 汝軍 | O19: 16 | P19: 3 | Q19: =P19/O19 -> 0.1875 | S19: 46262 | T19: 11 | V19: 46262 | W19: 2
A20: 後台 名單(ALL) | B20: =COUNTIF('2026初客紀錄'!C:C,"後台") -> 10 | C20: =B20-D20 -> 0 | D20: =COUNTIFS('2026初客紀錄'!C:C,"後台",'2026初客紀錄'!J:J,"<>") -> 10 | E20: =D20-F20-G20 -> 7 | F20: =COUNTIFS('2026初客紀錄'!C:C,"後台",'2026初客紀錄'!M:M,"未接")+COUNTIFS('2026初客紀錄'!C:C,"後台",'2026初客紀錄'!M:M,"語音") -> 3 | G20: =COUNTIFS('2026初客紀錄'!C:C,"後台",'2026初客紀錄'!K:K,"X") -> 0 | H20: =E20-J20 -> 5 | J20: =COUNTIFS('2026初客紀錄'!C:C,"後台",'2026初客紀錄'!K:K,"<>") -> 2 | K20: =J20/D20 -> 0.2 | M20: 6月 | N20: 空包彈 | P20: 41 | S20: 46263 | T20: 5 | V20: 46263 | W20: 2
A21: WIX | B21: =COUNTIF('2026初客紀錄'!C:C,"WIX") -> 5 | C21: =B21-D21 -> 0 | D21: =COUNTIFS('2026初客紀錄'!C:C,"WIX",'2026初客紀錄'!J:J,"<>") -> 5 | E21: =D21-F21-G21 -> 3 | F21: =COUNTIFS('2026初客紀錄'!C:C,"WIX",'2026初客紀錄'!M:M,"未接")+COUNTIFS('2026初客紀錄'!C:C,"WIX",'2026初客紀錄'!M:M,"語音") -> 2 | G21: =COUNTIFS('2026初客紀錄'!C:C,"WIX",'2026初客紀錄'!K:K,"X") -> 0 | H21: =E21-J21 -> 1 | J21: =COUNTIFS('2026初客紀錄'!C:C,"WIX",'2026初客紀錄'!K:K,"<>") -> 2 | K21: =J21/D21 -> 0.4 | M21: 7月 | N21: 子榕 | O21: 68 | P21: 32 | Q21: =P21/O21 -> 0.47058824 | S21: 總和 | T21: 110 | V21: 總和 | W21: 27
A22: LINE名單(ALL) | B22: =COUNTIF('2026初客紀錄'!C:C,"LINE") -> 23 | C22: =B22-D22 -> 1 | D22: =COUNTIFS('2026初客紀錄'!C:C,"LINE",'2026初客紀錄'!J:J,"<>") -> 22 | E22: =D22-F22-G22 -> 19 | F22: =COUNTIFS('2026初客紀錄'!C:C,"LINE",'2026初客紀錄'!M:M,"未接")+COUNTIFS('2026初客紀錄'!C:C,"LINE",'2026初客紀錄'!M:M,"語音") -> 3 | G22: =COUNTIFS('2026初客紀錄'!C:C,"LINE",'2026初客紀錄'!K:K,"X") -> 0 | H22: =E22-J22 -> 11 | J22: =COUNTIFS('2026初客紀錄'!C:C,"LINE",'2026初客紀錄'!K:K,"<>") -> 8 | K22: =J22/D22 -> 0.36363636 | M22: 7月 | N22: 汝軍 | O22: - | P22: - | Q22: =P22/O22 -> #VALUE!
A23: FB名單(ALL) | B23: =COUNTIF('2026初客紀錄'!C:C,"FB名單") -> 923 | C23: =B23-D23 -> 26 | D23: =COUNTIFS('2026初客紀錄'!C:C,"FB名單",'2026初客紀錄'!J:J,"<>") -> 897 | E23: =D23-F23-G23 -> 736 | F23: =COUNTIFS('2026初客紀錄'!C:C,"FB名單",'2026初客紀錄'!M:M,"未接")+COUNTIFS('2026初客紀錄'!C:C,"FB名單",'2026初客紀錄'!M:M,"語音") -> 145 | G23: =COUNTIFS('2026初客紀錄'!C:C,"FB名單",'2026初客紀錄'!K:K,"X") -> 16 | H23: =E23-J23 -> 532 | J23: =COUNTIFS('2026初客紀錄'!C:C,"FB名單",'2026初客紀錄'!K:K,"<>") -> 204 | K23: =J23/D23 -> 0.22742475 | M23: 7月 | N23: 空包彈 | P23: 28
A24: FB message(ALL) | B24: =COUNTIF('2026初客紀錄'!C:C,"FB") -> 2 | C24: =B24-D24 -> 0 | D24: =COUNTIFS('2026初客紀錄'!C:C,"FB",'2026初客紀錄'!J:J,"<>") -> 2 | E24: =D24-F24-G24 -> 1 | F24: =COUNTIFS('2026初客紀錄'!C:C,"FB",'2026初客紀錄'!M:M,"未接")+COUNTIFS('2026初客紀錄'!C:C,"FB",'2026初客紀錄'!M:M,"語音") -> 1 | G24: =COUNTIFS('2026初客紀錄'!C:C,"FB",'2026初客紀錄'!K:K,"X") -> 0 | H24: =E24-J24 -> 1 | J24: =COUNTIFS('2026初客紀錄'!C:C,"FB",'2026初客紀錄'!K:K,"<>") -> 0 | K24: =J24/D24 -> 0 | M24: 8月 | N24: 子榕 | O24: 110 | P24: 24 | Q24: =P24/O24 -> 0.21818182
A25: 家具or維修 | B25: =COUNTIF('2026初客紀錄'!C:C,"家具") -> 2 | D25: =COUNTIFS('2026初客紀錄'!C:C,"家具",'2026初客紀錄'!J:J,"<>") -> 2 | J25: =COUNTIFS('2026初客紀錄'!C:C,"家具",'2026初客紀錄'!J:J,"<>") -> 2 | K25: =J24/D24 -> 0 | M25: 8月 | N25: 汝軍 | O25: - | P25: - | Q25: =P25/O25 -> #VALUE!
A26: 總電話量(月) | B26: 數量 | C26: 未撥 | D26: 已撥 | E26: 已接 | F26: 未接+語音 | G26: 其他 無效 | H26: 已接 未約成 | I26: 家具 | J26: 預約 成功 | K26: 成功率 % | M26: 8月 | N26: 空包彈 | P26: 26
A27: 1月 | B27: =COUNTIFS('2026初客紀錄'!B:B,">=2026/1/1",'2026初客紀錄'!B:B,"<=2026/1/31") -> 218 | C27: =B27-D27 -> 2 | D27: =COUNTIFS('2026初客紀錄'!B:B,">=2026/1/1",'2026初客紀錄'!B:B,"<=2026/1/31",'2026初客紀錄'!J:J,"<>") -> 216 | E27: =D27-F27-G27 -> 176 | F27: =COUNTIFS('2026初客紀錄'!B:B,">=2026/1/1",'2026初客紀錄'!B:B,"<=2026/1/31",'2026初客紀錄'!M:M,"未接")+COUNTIFS('2026初客紀錄'!B:B,">=2026/1/1",'2026初客紀錄'!B:B,"<=2026/1/31",'2026初客紀錄'!M:M,"語音") -> 40 | G27: =COUNTIFS( '2026初客紀錄'!B:B,">="&DATE(2026,1,1), '2026初客紀錄'!B:B,"<"&DATE(2026,1,31), '2026初客紀錄'!K:K,"X" ) -> 0 | H27: =E27-J27 -> 133 | I27: =COUNTIFS( '2026初客紀錄'!B:B,">="&DATE(2026,1,1), '2026初客紀錄'!B:B,"<"&DATE(2026,1,31), '2026初客紀錄'!C:C,"家具" ) -> 0 | J27: =COUNTIFS('2026初客紀錄'!B:B,">=2026/1/1",'2026初客紀錄'!B:B,"<=2026/1/31",'2026初客紀錄'!K:K,"<>") -> 43 | K27: =J27/(D27-I27) -> 0.19907407
A28: 2月 | B28: =COUNTIFS('2026初客紀錄'!B:B,">=2026/2/1",'2026初客紀錄'!B:B,"<=2026/2/28") -> 107 | C28: =B28-D28 -> 2 | D28: =COUNTIFS('2026初客紀錄'!B:B,">=2026/2/1",'2026初客紀錄'!B:B,"<=2026/2/28",'2026初客紀錄'!J:J,"<>") -> 105 | E28: =D28-F28-G28 -> 93 | F28: =COUNTIFS('2026初客紀錄'!B:B,">=2026/2/1",'2026初客紀錄'!B:B,"<=2026/2/28",'2026初客紀錄'!M:M,"未接")+COUNTIFS('2026初客紀錄'!B:B,">=2026/2/1",'2026初客紀錄'!B:B,"<=2026/2/28",'2026初客紀錄'!M:M,"語音") -> 12 | G28: =COUNTIFS( '2026初客紀錄'!B:B,">="&DATE(2026,2,1), '2026初客紀錄'!B:B,"<"&DATE(2026,2,28), '2026初客紀錄'!K:K,"X" ) -> 0 | H28: =E28-J28 -> 79 | I28: =COUNTIFS( '2026初客紀錄'!B:B,">="&DATE(2026,2,1), '2026初客紀錄'!B:B,"<"&DATE(2026,2,28), '2026初客紀錄'!C:C,"家具" ) -> 0 | J28: =COUNTIFS('2026初客紀錄'!B:B,">=2026/2/1",'2026初客紀錄'!B:B,"<=2026/2/28",'2026初客紀錄'!K:K,"<>") -> 14 | K28: =J28/(D28-I28) -> 0.13333333
A29: 3月 | B29: =COUNTIFS('2026初客紀錄'!B:B,">=2026/3/1",'2026初客紀錄'!B:B,"<=2026/3/31") -> 134 | C29: =B29-D29 -> 5 | D29: =COUNTIFS('2026初客紀錄'!B:B,">=2026/3/1",'2026初客紀錄'!B:B,"<=2026/3/31",'2026初客紀錄'!J:J,"<>") -> 129 | E29: =D29-F29-G29 -> 123 | F29: =COUNTIFS('2026初客紀錄'!B:B,">=2026/3/1",'2026初客紀錄'!B:B,"<=2026/3/31",'2026初客紀錄'!M:M,"未接")+COUNTIFS('2026初客紀錄'!B:B,">=2026/3/1",'2026初客紀錄'!B:B,"<=2026/3/31",'2026初客紀錄'!M:M,"語音") -> 6 | G29: =COUNTIFS( '2026初客紀錄'!B:B,">="&DATE(2026,3,1), '2026初客紀錄'!B:B,"<"&DATE(2026,3,31), '2026初客紀錄'!K:K,"X" ) -> 0 | H29: =E29-J29 -> 85 | I29: =COUNTIFS( '2026初客紀錄'!B:B,">="&DATE(2026,3,1), '2026初客紀錄'!B:B,"<"&DATE(2026,3,31), '2026初客紀錄'!C:C,"家具" ) -> 0 | J29: =COUNTIFS('2026初客紀錄'!B:B,">=2026/3/1",'2026初客紀錄'!B:B,"<=2026/3/31",'2026初客紀錄'!K:K,"<>") -> 38 | K29: =J29/(D29-I29) -> 0.29457364
A30: 4月 | B30: =COUNTIFS('2026初客紀錄'!B:B,">=2026/4/1",'2026初客紀錄'!B:B,"<=2026/4/30") -> 46 | C30: =B30-D30 -> 1 | D30: =COUNTIFS('2026初客紀錄'!B:B,">=2026/4/1",'2026初客紀錄'!B:B,"<=2026/4/30",'2026初客紀錄'!J:J,"<>") -> 45 | E30: =D30-F30-G30 -> 42 | F30: =COUNTIFS('2026初客紀錄'!B:B,">=2026/4/1",'2026初客紀錄'!B:B,"<=2026/4/30",'2026初客紀錄'!M:M,"未接")+COUNTIFS('2026初客紀錄'!B:B,">=2026/4/1",'2026初客紀錄'!B:B,"<=2026/4/30",'2026初客紀錄'!M:M,"語音") -> 3 | G30: =COUNTIFS( '2026初客紀錄'!B:B,">="&DATE(2026,4,1), '2026初客紀錄'!B:B,"<"&DATE(2026,4,30), '2026初客紀錄'!K:K,"X" ) -> 0 | H30: =E30-J30 -> 31 | I30: =COUNTIFS( '2026初客紀錄'!B:B,">="&DATE(2026,4,1), '2026初客紀錄'!B:B,"<"&DATE(2026,4,30), '2026初客紀錄'!C:C,"家具" ) -> 0 | J30: =COUNTIFS('2026初客紀錄'!B:B,">=2026/4/1",'2026初客紀錄'!B:B,"<=2026/4/30",'2026初客紀錄'!K:K,"<>") -> 11 | K30: =J30/(D30-I30) -> 0.24444444
A31: 5月 | B31: =COUNTIFS('2026初客紀錄'!B:B,">=2026/5/1",'2026初客紀錄'!B:B,"<=2026/5/31") -> 96 | C31: =B31-D31 -> 3 | D31: =COUNTIFS('2026初客紀錄'!B:B,">=2026/5/1",'2026初客紀錄'!B:B,"<=2026/5/31",'2026初客紀錄'!J:J,"<>") -> 93 | E31: =D31-F31-G31 -> 86 | F31: =COUNTIFS('2026初客紀錄'!B:B,">=2026/5/1",'2026初客紀錄'!B:B,"<=2026/5/31",'2026初客紀錄'!M:M,"未接")+COUNTIFS('2026初客紀錄'!B:B,">=2026/7/1",'2026初客紀錄'!B:B,"<=2026/7/31",'2026初客紀錄'!M:M,"語音") -> 7 | G31: =COUNTIFS( '2026初客紀錄'!B:B,">="&DATE(2026,5,1), '2026初客紀錄'!B:B,"<"&DATE(2026,5,31), '2026初客紀錄'!K:K,"X" ) -> 0 | H31: =E31-J31 -> 62 | I31: =COUNTIFS( '2026初客紀錄'!B:B,">="&DATE(2026,5,1), '2026初客紀錄'!B:B,"<"&DATE(2026,5,31), '2026初客紀錄'!C:C,"家具" ) -> 0 | J31: =COUNTIFS('2026初客紀錄'!B:B,">=2026/5/1",'2026初客紀錄'!B:B,"<=2026/5/31",'2026初客紀錄'!K:K,"<>") -> 24 | K31: =J31/(D31-I31) -> 0.25806452
A32: 6月 | B32: =COUNTIFS('2026初客紀錄'!B:B,">=2026/6/1",'2026初客紀錄'!B:B,"<=2026/6/30") -> 140 | C32: =B32-D32 -> 5 | D32: =COUNTIFS('2026初客紀錄'!B:B,">=2026/6/1",'2026初客紀錄'!B:B,"<=2026/6/30",'2026初客紀錄'!J:J,"<>") -> 135 | E32: =D32-F32-G32 -> 93 | F32: =COUNTIFS('2026初客紀錄'!B:B,">=2026/6/1",'2026初客紀錄'!B:B,"<=2026/6/30",'2026初客紀錄'!M:M,"未接")+ COUNTIFS('2026初客紀錄'!B:B,">=2026/6/1",'2026初客紀錄'!B:B,"<=2026/6/30",'2026初客紀錄'!M:M,"語音") -> 34 | G32: =COUNTIFS( '2026初客紀錄'!B:B,">="&DATE(2026,6,1), '2026初客紀錄'!B:B,"<"&DATE(2026,6,30), '2026初客紀錄'!K:K,"X" ) -> 8 | H32: =E32-J32 -> 63 | I32: =COUNTIFS( '2026初客紀錄'!B:B,">="&DATE(2026,6,1), '2026初客紀錄'!B:B,"<"&DATE(2026,6,30), '2026初客紀錄'!C:C,"家具" ) -> 0 | J32: =COUNTIFS('2026初客紀錄'!B:B,">=2026/6/1",'2026初客紀錄'!B:B,"<=2026/6/30",'2026初客紀錄'!K:K,"<>") -> 30 | K32: =J32/(D32-I32) -> 0.22222222
A33: 7月 | B33: =COUNTIFS('2026初客紀錄'!B:B,">=2026/7/1",'2026初客紀錄'!B:B,"<=2026/7/31") -> 115 | C33: =B33-D33 -> 6 | D33: =COUNTIFS('2026初客紀錄'!B:B,">=2026/7/1",'2026初客紀錄'!B:B,"<=2026/7/31",'2026初客紀錄'!J:J,"<>") -> 109 | E33: =D33-F33-G33 -> 82 | F33: =COUNTIFS('2026初客紀錄'!B:B,">=2026/7/1",'2026初客紀錄'!B:B,"<=2026/7/31",'2026初客紀錄'!M:M,"未接")+COUNTIFS('2026初客紀錄'!B:B,">=2026/7/1",'2026初客紀錄'!B:B,"<=2026/7/31",'2026初客紀錄'!M:M,"語音") -> 27 | G33: =COUNTIFS( '2026初客紀錄'!B:B,">="&DATE(2026,7,1), '2026初客紀錄'!B:B,"<"&DATE(2026,7/31), '2026初客紀錄'!K:K,"X" ) -> 0 | H33: =E33-J33 -> 49 | I33: =COUNTIFS( '2026初客紀錄'!B:B,">="&DATE(2026,7,1), '2026初客紀錄'!B:B,"<"&DATE(2026,7,31), '2026初客紀錄'!C:C,"家具" ) -> 0 | J33: =COUNTIFS('2026初客紀錄'!B:B,">=2026/7/1",'2026初客紀錄'!B:B,"<=2026/7/31",'2026初客紀錄'!K:K,"<>") -> 33 | K33: =J33/(D33-I33) -> 0.30275229
A34: 8月 | B34: =COUNTIFS('2026初客紀錄'!B:B,">=2026/8/1",'2026初客紀錄'!B:B,"<=2026/8/31") -> 109 | C34: =B34-D34 -> 3 | D34: =COUNTIFS('2026初客紀錄'!B:B,">=2026/8/1",'2026初客紀錄'!B:B,"<=2026/8/31",'2026初客紀錄'!J:J,"<>") -> 106 | E34: =D34-F34-G34 -> 75 | F34: =COUNTIFS('2026初客紀錄'!B:B,">=2026/8/1",'2026初客紀錄'!B:B,"<=2026/8/31",'2026初客紀錄'!M:M,"未接")+COUNTIFS('2026初客紀錄'!B:B,">=2026/7/1",'2026初客紀錄'!B:B,"<=2026/7/31",'2026初客紀錄'!M:M,"語音") -> 26 | G34: 5 | H34: =E34-J34 -> 49 | I34: =COUNTIFS( '2026初客紀錄'!B:B,">="&DATE(2026,8,1), '2026初客紀錄'!B:B,"<"&DATE(2026,8,31), '2026初客紀錄'!C:C,"家具" ) -> 2 | J34: =COUNTIFS('2026初客紀錄'!B:B,">=2026/8/1",'2026初客紀錄'!B:B,"<=2026/8/31",'2026初客紀錄'!K:K,"<>") -> 26 | K34: =J34/(D34-I34) -> 0.25

Sheet 每週業務追蹤表
G1: 價格、付款、規格、選配、運送、合約、交期
A2: 遊學日期 | B2: 客戶 | C2: 類型 | D2: 能力(客觀) | E2: 訪後意願 | F2: 意願(表格) | G2: 談條件(方案) | H2: 等級 | I2: 卡點 | J2: 業務下一步 | K2: 備註
A3: 5/2(六) | B3: 藍貝芝 0935546501 | C3: 退休長住 | F3: 高 | H3: A | I3: 找地中
B4: 蘇建豪 0912032722 | C4: 假日休閒 | D4: 無地 | F4: 高 | H4: A | J4: 租地
B5: 陳桃霞 0958586876 | C5: 假日休閒 | D5: 宜蘭 | F5: 中 | G5: 80~120萬 | H5: B | K5: 弟弟是建築師,狹長基地
B6: 黃淑華 0923249393 | C6: 假日休閒 | F6: 中 | H6: B
B7: 張宇翔 0981528028 | C7: 假日休閒 | D7: 苗栗通霄 | F7: 高 | H7: A | K7: 承廷聯繫中
A8: 5/8(五) | B8: 鄭惠分 0910699428 | C8: 假日休閒 | D8: 台南南化 | F8: 中 | H8: B | I8: 整地,申請水電
B9: 王宇晴 0955703113 | C9: 退休長住 | D9: 彰化老家地 | F9: 低 | G9: 先生是醫生 | H9: C | K9: 双院、陽台
B10: 莊雅茹 0966786729 | C10: 退休長住 | D10: 中壢 | F10: 高 | H10: A | K10: 合掌屋
A11: 5/9(六) | B11: 楊(沈慧玲) 0933183284 | C11: 假日休閒 | D11: 西湖地 | F11: 高 | H11: A | K11: 已場勘
B12: 温雅惠 0922011800 | C12: 退休長住 | D12: 無地 | F12: 高 | G12: 先生說400萬 | H12: B | K12: 想等后土村
A13: 5/13(三) | B13: 林慧英 0931692178 | C13: 退休長住 | D13: 找地中 | F13: 中 | G13: 500萬 | H13: B
B14: 黃惠如 0922212227 | C14: 假日休閒 | D14: 老家枋寮基地 | F14: 高 | G14: 300萬 | H14: A | I14: 也再看高雄建案 | K14: 衛浴客製需求
B15: 張又文 0933191026 | C15: 休閒業者 | D15: 國姓農地 | F15: 高 | G15: 300萬 | H15: A | I15: 申請休閒農場 | K15: 有給基地資訊 | L15: 現場有鐵皮屋要拆
A16: 5/16(六) | B16: 陳延靜 0928329069 | C16: 退休長住 | D16: 老家地 | F16: 低 | H16: B | K16: 先來了解
B17: 陳讚昌 0923263858 | C17: 退休長住 | D17: 宜蘭基地 | F17: 低 | H17: C | K17: 投資客心態,會殺價
B18: 傅文賢 0975929028 | C18: 休閒業者 | D18: 桃園&新竹 | F18: 低 | H18: B | I18: 投資
B19: 楊永權 0922003775 | C19: 休閒業者 | D19: 同上 | F19: 低 | H19: B | I19: 投資
B20: 吳尚溢 0912772372 | C20: 休閒業者 | D20: 同上 | F20: 低 | H20: B | I20: 投資
A21: 5/23(六) | B21: 鄭艾綸 0927701299 | C21: 假日休閒 | F21: 高 | H21: B | K21: 無地,但問很細
B22: 陳彥儒 0960135688 | C22: 退休長住 | F22: 低 | H22: B | K22: 目標2院,希望快速,父母也無聽簡報即趕行程離開
B23: 陳美妙 0912678885 | C23: 假日休閒 | F23: 低 | H23: C | K23: 太熱,看完合掌屋即離開,體驗感差,是否邀約下回參觀完工合掌屋招待參觀費?
B24: 陳郁雯 0972053143 | C24: 假日休閒 | D24: 土地： 水、電、道路： 預算： 決策： 時間： | F24: 高 | G24: 屋款： | H24: B | K24: 高度興趣
A25: 5/29(五) | B25: 羅桂華 0963158190 | C25: 退休長住 | D25: 土地：臺中市石岡區崁子下段(5927)947-1地號 水、電、道路：水電X 道路O 預算：400+ 決策：先生 時間： | F25: 高 | G25: 合掌屋 | H25: A | I25: 水電 | J25: 追客人申請水電
B26: 林煜騰 0963638877 | C26: 假日休閒 | D26: 土地：桃園青埔(農地1200坪/建地258坪) 水、電、道路：有電 預算： 決策：自己 時間： | F26: 低 | G26: 合掌屋 | H26: A | I26: 投資 | J26: 局勢不好先做好一間，照顧自己，也作為未來投資想法DEMO | K26: HM:是小建商
A27: 6/3(三) | B27: 白詠 0928933955 | C27: 其他 | D27: 土地：三義 水、電、道路：水電O 道路O 預算： 決策：先生 時間： | F27: 低 | H27: C | K27: 軍: 用途似乎不明確
B28: 楊淑惠 0936826965 | C28: 假日休閒 | D28: 土地：X 水、電、道路：水電X 道路X 預算： 決策：自己 時間： | F28: 高 | G28: 雙院 | H28: B | J28: 關心客人找地狀況
B29: 曾銘圳 0932527933 | C29: 假日休閒 | D29: 土地：三灣 水、電、道路：水電X 道路O 預算： 決策：先生 時間： | F29: 高 | G29: 合掌屋 | H29: B | J29: 追蹤客人申請水電
A30: 6/6六 | B30: 蔣小梅 0932947981 | C30: 假日休閒 | D30: 土地：森優生態實驗小學 水、電、道路：水電O 道路? 預算：400+ 決策：先生 時間： | F30: 中 | G30: 合掌屋 | H30: A | I30: 到底要放在哪裡？ | J30: 追蹤實際意願
B31: 吳之琳 0906950910 | C31: 假日休閒 | D31: 土地：古坑 水、電、道路：水O 電X 道路? 預算：300-350 決策：自己 (住 夫妻) 時間：請到電後越快越好 | F31: 高 | G31: 短3 or 2院(不排斥舊款出清) | H31: A | I31: 電 | J31: 追客人請電
B32: 蔡慈愛 0988722930 | C32: 假日休閒 | D32: 土地：新營 水、電、道路：水電O 道路O 預算：OK 決策：先生(業主) 時間： | F32: 中 | G32: 大單院客製(空屋改牆做茶室) | H32: A | I32: 設計案 | J32: 設計師跟業主討論後，會加3方群 然後提供進一步設計需求
A33: 4/18六 | B33: 林意馨 0912156377 | C33: 假日休閒 | D33: 土地：大湖 水、電、道路：水電O 道路O 預算：150-200 決策：先生 時間： | E33: 高 | F33: 中 | G33: 双院 | H33: B | I33: 合法性 資材室 | J33: 客戶已經跟水保師說明我們的木屋，但水保師說，不會有人蓋這麼漂亮的房子。 讓客人自己想想，過不過的了這關。
A34: 45839 | B34: 蔡奇玲 0953707008 | C34: 其他 | D34: 土地：清水 水、電、道路：水電X 道路? 預算：500內 決策： 時間： | E34: 中 | F34: 高 | G34: ? 3院or 合掌屋 不用有睡覺的空間 想成為獨立書屋 森林中的小書屋 | H34: A | I34: 合法性 已經初步動搖 | J34: 要重看，太久了 客戶已經再詢問不合法怎麼請到建地的水電 | K34: 錢不夠不用想合法 2026/6/17更新
A35: 46190 | B35: 高先生 0913151931 | D35: 土地：X 水、電、道路： 預算：有錢(老闆判斷) 決策： 時間： | E35: 中 | F35: 中 | H35: B | I35: 風水，太太堅持要有導角，合掌屋的屋頂是刀煞 (可見這個人有很多害怕)
A36: 46190 | B36: 陳小惠 0952894849 | C36: 假日休閒 | D36: 土地：苑裡300坪農地 水、電、道路：水電O 道路? 預算：有錢(老闆判斷)朋友紅屋家具 決策： 時間： | E36: 高 | F36: 中 | H36: A | I36: 朋友?? | J36: 再去電確認
A37: 46185 | B37: 周啟陽 0910464020 | C37: 退休長住 | D37: 給長輩，但現場感覺是同行(老闆&成廷認證) | E37: 低 | F37: 低 | H37: C
A38: 46190 | B38: 曾琴梅 0939705120 | C38: 退休長住 | D38: 土地：苗栗公館(還再談) 60坪丙建 水、電、道路： 預算： 決策： 時間： | E38: 中 | F38: 高 | G38: 合掌屋 | H38: B | I38: 無地 | J38: 建議租地
A39: 46185 | B39: 陳怡君 0932787553 | C39: 退休長住 | D39: 土地：嘉義民雄虎尾寮 200坪 水、電、道路：水電O 道路?(沒去過) 預算： 決策：500 時間： 土地：弟弟的，同意可用 | E39: 中 | F39: 中 | G39: 合掌屋+大單(頌缽) | H39: A | I39: ??? | J39: 取得地號，照片 | K39: 買過出清Qcamp 20萬
